[2025-05-18T06:17:20.156+0000] {taskinstance.py:1159} INFO - Dependencies all met for dep_context=non-requeueable deps ti=<TaskInstance: brewery_pipeline_bronze_silver_gold.extract_bronze_data manual__2025-05-18T06:17:13.841328+00:00 [queued]>
[2025-05-18T06:17:20.173+0000] {taskinstance.py:1159} INFO - Dependencies all met for dep_context=requeueable deps ti=<TaskInstance: brewery_pipeline_bronze_silver_gold.extract_bronze_data manual__2025-05-18T06:17:13.841328+00:00 [queued]>
[2025-05-18T06:17:20.173+0000] {taskinstance.py:1361} INFO - Starting attempt 1 of 2
[2025-05-18T06:17:20.204+0000] {taskinstance.py:1382} INFO - Executing <Task(PythonOperator): extract_bronze_data> on 2025-05-18 06:17:13.841328+00:00
[2025-05-18T06:17:20.211+0000] {standard_task_runner.py:57} INFO - Started process 81 to run task
[2025-05-18T06:17:20.216+0000] {standard_task_runner.py:84} INFO - Running: ['***', 'tasks', 'run', 'brewery_pipeline_bronze_silver_gold', 'extract_bronze_data', 'manual__2025-05-18T06:17:13.841328+00:00', '--job-id', '18', '--raw', '--subdir', 'DAGS_FOLDER/brewery_pipeline_bronze_silver_gold.py', '--cfg-path', '/tmp/tmp6ydu3hxa']
[2025-05-18T06:17:20.220+0000] {standard_task_runner.py:85} INFO - Job 18: Subtask extract_bronze_data
[2025-05-18T06:17:20.246+0000] {logging_mixin.py:151} WARNING - /home/***/.local/lib/python3.10/site-packages/***/settings.py:193 DeprecationWarning: The sql_alchemy_conn option in [core] has been moved to the sql_alchemy_conn option in [database] - the old setting has been used, but please update your config.
[2025-05-18T06:17:20.291+0000] {task_command.py:416} INFO - Running <TaskInstance: brewery_pipeline_bronze_silver_gold.extract_bronze_data manual__2025-05-18T06:17:13.841328+00:00 [running]> on host 293766d45543
[2025-05-18T06:17:20.410+0000] {taskinstance.py:1662} INFO - Exporting env vars: AIRFLOW_CTX_DAG_OWNER='mateus' AIRFLOW_CTX_DAG_ID='brewery_pipeline_bronze_silver_gold' AIRFLOW_CTX_TASK_ID='extract_bronze_data' AIRFLOW_CTX_EXECUTION_DATE='2025-05-18T06:17:13.841328+00:00' AIRFLOW_CTX_TRY_NUMBER='1' AIRFLOW_CTX_DAG_RUN_ID='manual__2025-05-18T06:17:13.841328+00:00'
[2025-05-18T06:17:20.424+0000] {taskinstance.py:1937} ERROR - Task failed with exception
Traceback (most recent call last):
  File "/home/airflow/.local/lib/python3.10/site-packages/urllib3/connection.py", line 174, in _new_conn
    conn = connection.create_connection(
  File "/home/airflow/.local/lib/python3.10/site-packages/urllib3/util/connection.py", line 72, in create_connection
    for res in socket.getaddrinfo(host, port, family, socket.SOCK_STREAM):
  File "/usr/local/lib/python3.10/socket.py", line 955, in getaddrinfo
    for res in _socket.getaddrinfo(host, port, family, type, proto, flags):
socket.gaierror: [Errno -3] Temporary failure in name resolution

During handling of the above exception, another exception occurred:

Traceback (most recent call last):
  File "/home/airflow/.local/lib/python3.10/site-packages/urllib3/connectionpool.py", line 714, in urlopen
    httplib_response = self._make_request(
  File "/home/airflow/.local/lib/python3.10/site-packages/urllib3/connectionpool.py", line 403, in _make_request
    self._validate_conn(conn)
  File "/home/airflow/.local/lib/python3.10/site-packages/urllib3/connectionpool.py", line 1053, in _validate_conn
    conn.connect()
  File "/home/airflow/.local/lib/python3.10/site-packages/urllib3/connection.py", line 363, in connect
    self.sock = conn = self._new_conn()
  File "/home/airflow/.local/lib/python3.10/site-packages/urllib3/connection.py", line 186, in _new_conn
    raise NewConnectionError(
urllib3.exceptions.NewConnectionError: <urllib3.connection.HTTPSConnection object at 0x79d4825bd600>: Failed to establish a new connection: [Errno -3] Temporary failure in name resolution

During handling of the above exception, another exception occurred:

Traceback (most recent call last):
  File "/home/airflow/.local/lib/python3.10/site-packages/requests/adapters.py", line 486, in send
    resp = conn.urlopen(
  File "/home/airflow/.local/lib/python3.10/site-packages/urllib3/connectionpool.py", line 798, in urlopen
    retries = retries.increment(
  File "/home/airflow/.local/lib/python3.10/site-packages/urllib3/util/retry.py", line 592, in increment
    raise MaxRetryError(_pool, url, error or ResponseError(cause))
urllib3.exceptions.MaxRetryError: HTTPSConnectionPool(host='api.openbrewerydb.org', port=443): Max retries exceeded with url: /v1/breweries?per_page=50 (Caused by NewConnectionError('<urllib3.connection.HTTPSConnection object at 0x79d4825bd600>: Failed to establish a new connection: [Errno -3] Temporary failure in name resolution'))

During handling of the above exception, another exception occurred:

Traceback (most recent call last):
  File "/home/airflow/.local/lib/python3.10/site-packages/airflow/operators/python.py", line 192, in execute
    return_value = self.execute_callable()
  File "/home/airflow/.local/lib/python3.10/site-packages/airflow/operators/python.py", line 209, in execute_callable
    return self.python_callable(*self.op_args, **self.op_kwargs)
  File "/opt/airflow/dags/brewery_pipeline_bronze_silver_gold.py", line 22, in extract_bronze_data
    response = requests.get(url)
  File "/home/airflow/.local/lib/python3.10/site-packages/requests/api.py", line 73, in get
    return request("get", url, params=params, **kwargs)
  File "/home/airflow/.local/lib/python3.10/site-packages/requests/api.py", line 59, in request
    return session.request(method=method, url=url, **kwargs)
  File "/home/airflow/.local/lib/python3.10/site-packages/requests/sessions.py", line 589, in request
    resp = self.send(prep, **send_kwargs)
  File "/home/airflow/.local/lib/python3.10/site-packages/requests/sessions.py", line 703, in send
    r = adapter.send(request, **kwargs)
  File "/home/airflow/.local/lib/python3.10/site-packages/requests/adapters.py", line 519, in send
    raise ConnectionError(e, request=request)
requests.exceptions.ConnectionError: HTTPSConnectionPool(host='api.openbrewerydb.org', port=443): Max retries exceeded with url: /v1/breweries?per_page=50 (Caused by NewConnectionError('<urllib3.connection.HTTPSConnection object at 0x79d4825bd600>: Failed to establish a new connection: [Errno -3] Temporary failure in name resolution'))
[2025-05-18T06:17:20.436+0000] {taskinstance.py:1400} INFO - Marking task as UP_FOR_RETRY. dag_id=brewery_pipeline_bronze_silver_gold, task_id=extract_bronze_data, execution_date=20250518T061713, start_date=20250518T061720, end_date=20250518T061720
[2025-05-18T06:17:20.459+0000] {standard_task_runner.py:104} ERROR - Failed to execute job 18 for task extract_bronze_data (HTTPSConnectionPool(host='api.openbrewerydb.org', port=443): Max retries exceeded with url: /v1/breweries?per_page=50 (Caused by NewConnectionError('<urllib3.connection.HTTPSConnection object at 0x79d4825bd600>: Failed to establish a new connection: [Errno -3] Temporary failure in name resolution')); 81)
[2025-05-18T06:17:20.508+0000] {local_task_job_runner.py:228} INFO - Task exited with return code 1
[2025-05-18T06:17:20.544+0000] {taskinstance.py:2778} INFO - 0 downstream tasks scheduled from follow-on schedule check
